I'm sorry, but an uncaught exception occurred.

While running game code:
  File "game/script.rpy", line 1063, in script
    pov "[i]Nobody’s here yet.[/i]"
KeyError: u'i'

-- Full Traceback ------------------------------------------------------------

Full traceback:
  File "game/script.rpy", line 1063, in script
    pov "[i]Nobody’s here yet.[/i]"
  File "C:\Users\ColH\Downloads\renpy-6.18.2-sdk\renpy-6.18.2-sdk\renpy\ast.py", line 593, in execute
    renpy.exports.say(who, what, interact=self.interact)
  File "C:\Users\ColH\Downloads\renpy-6.18.2-sdk\renpy-6.18.2-sdk\renpy\exports.py", line 998, in say
    who(what, interact=interact)
  File "C:\Users\ColH\Downloads\renpy-6.18.2-sdk\renpy-6.18.2-sdk\renpy\character.py", line 817, in __call__
    what = what_pattern.replace("[what]", sub(what, translate=translate))
  File "C:\Users\ColH\Downloads\renpy-6.18.2-sdk\renpy-6.18.2-sdk\renpy\character.py", line 799, in sub
    return renpy.substitutions.substitute(s, scope=scope, force=force, translate=translate)[0]
  File "C:\Users\ColH\Downloads\renpy-6.18.2-sdk\renpy-6.18.2-sdk\renpy\substitutions.py", line 229, in substitute
    s = formatter.vformat(s, (), kwargs)
  File "/home/tom/ab/x64lucid-deps/install/lib/python2.7/string.py", line 549, in vformat
  File "/home/tom/ab/x64lucid-deps/install/lib/python2.7/string.py", line 571, in _vformat
  File "/home/tom/ab/x64lucid-deps/install/lib/python2.7/string.py", line 632, in get_field
  File "/home/tom/ab/x64lucid-deps/install/lib/python2.7/string.py", line 591, in get_value
KeyError: u'i'

Windows-7-6.1.7601-SP1
Ren'Py 6.18.2.729
Doctor Sim 0.0
